Workbook
Name consistency: Lists!$E$2:$E$4
Name quality: Lists!$F$2:$F$4
Name strength: 'Scoring Requirements'!$B$40:$B$43
Name sustainable: Lists!$G$2:$G$4

Sheet Assessment Guidance
B2: Governance Core Assessment
B3: Assessment Guideline
B5: Introduction
C6: This assessment guideline supports both internal self-assessments and external assessments of the Governance Core within the Safety Energy Loop Framework. The guideline is not an assessment tool in itself. It is a supporting resource designed to help assessors understand the intent of the governance criteria, how the elements connect, and how system maturity presents in practice. It is intended to guide professional judgement, not replace it. Assessors are expected to move beyond a traditional audit approach. The most valuable insights will come from conversations, observation, and testing how governance operates under normal conditions and under pressure, rather than relying solely on document review.
B8: Section One | C8: General Assessment Principles
C9: This section outlines the principles that underpin a credible and value-adding governance assessment. These principles apply to all elements of the Governance Core and should be applied consistently, whether the assessment is conducted as a self-review or by an external assessor. The purpose of the assessment is to understand how well the governance system functions, not simply whether components exist. Key principles include: • Assess the system as a whole, not individual documents in isolation. Governance elements are interconnected and should be evaluated in combination. • Focus on how governance influences real decisions, behaviours, and outcomes, particularly for high-risk work. • Use multiple sources of evidence, including documentation, interviews, field observations, and lived experience. • Test alignment between what is described, what is demonstrated, and what is experienced by people at different levels. • Avoid checklist-based scoring. Professional judgement is required to determine maturity based on patterns and consistency. • Seek evidence of intent being translated into action, not just stated expectations. • Look for both strengths and system constraints. The goal is insight and improvement, not compliance confirmation. Assessments should produce outcomes that are accurate, objective, reliable, and genuinely useful to the organisation. Where gaps are identified, assessors should aim to describe why they exist and how they affect system performance.
B11: Section Two | C11: Assessment References
C12: This section provides reference material to help assessors interpret maturity levels and understand how governance maturity presents in practice. Rather than prescribing a fixed list of evidence, this section describes what governance maturity typically looks like, sounds like, and feels like when it is operating effectively as part of an integrated management system. Assessors are encouraged to test what they have observed, reviewed, and experienced against: • Process - the defined relationship and flow between components of the system. • People - the effective integration of human energy in enabling components of the system to be effective and/or interact as designed. • Systems – the formal structures, processes, decision rules, and governance mechanisms in place. • Symbols – what is visibly prioritised, reinforced, and valued across the organisation. • Behaviours – how leaders and workers interact with governance processes in real situations. Where opportunities for improvement are identified, assessors should align observations to the maturity descriptors used in this framework. Language should describe system behaviour and governance effectiveness, rather than individual performance. The examples provided are intended as guidance only. They are not exhaustive, and assessors are expected to apply judgement based on the organisation’s context, risk profile, and operating environment.

Sheet PART A - Governance
A1: Category | B1: Intent and fundamental criteria | C1: Reactive Safety is largely reactive, fragmented and person-dependent, with little shared understanding, inconsistent practices and minimal system coherence. Decisions are primarily driven by production or compliance pressures rather than an articulated view of risk. | D1: Proactive Safety systems are established and broadly understood, but application and influence on decisions are uneven across the organisation. Performance relies on emerging structures and capable leaders rather than a fully embedded, self-sustaining system. | E1: Resilient Safety is fully integrated into how work is designed, decided and delivered, with clear, shared understanding of risk across all levels of the organisation. The system is self-sustaining and continuously improving, with decisions consistently guided by evidence, learning and a long-term view of risk reduction.
A2: LEADERSHIP & ACCOUNTABILITY | B2: Intent: Leadership sets the direction for safety, visibly owns risk, and is accountable for system performance and outcomes, ensuring that safety is consistently prioritised in decisions, behaviours, and resource allocation across the organisation.
B3: 1.1 Leadership Intent and Expectations Leadership clearly defines what safety means for the organisation and translates that intent into consistent expectations for how work is planned and decided. Focus Areas Clarity and consistency of leadership safety intent Translation of intent into roles, expectations and decisions Shared understanding of safety intent across leadership layers Visible alignment between what leaders say and what they do | C3: What it looks like Safety intent exists, but it is expressed as broad values or slogans rather than decision rules. Expectations for leaders and supervisors are implied rather than clearly stated. Different leaders describe safety priorities in different ways. Safety requirements are heavily document-based and feel separate from operational planning. What it sounds like “Safety is important” without being able to define what that means in decisions. “Just follow the procedure” used as the default response to risk issues. “That’s HSE’s job” said directly or indirectly. What it feels like Teams are unsure what leadership expects when risk and production conflict. Safety messaging changes depending on the leader, the site, or the week. Typical activities and routines Safety is discussed, but mostly after something goes wrong or when audits are due. Plans exist, but safety considerations often appear late in planning or only in approval steps. | D3: What it looks like Leadership intent is clearer and more stable, with a shared language that most leaders use consistently. Expectations are written into leader responsibilities and planning routines. Leaders increasingly reference safety intent during planning, approvals, and resourcing discussions. Safety expectations are clearer for supervisors, especially around stop-work and escalation. What it sounds like “Here is how we decide when risk changes” “What is the control that prevents serious harm here” “If we cannot verify the control, we do not proceed” What it feels like People can predict how leaders will respond to high-risk situations. Expectations are clearer, even if execution still varies between areas. Typical activities and routines Leaders routinely participate in risk conversations, not only compliance checks. Planning includes safety considerations earlier, particularly for high-risk work. Leaders test understanding through questions, not just reminders. | E3: What it looks like Leadership intent is operational and decision-based, with clear non-negotiables and clear boundaries. Expectations are consistently applied across teams, sites, and contractors. Safety intent is embedded into planning, work design, and operational decision forums. Leaders model the expected behaviours under pressure, not only in calm conditions. What it sounds like “We are not resourcing this unless we can control the risk” “Stop-work is expected when controls degrade” “Show me the evidence the critical controls are working today” What it feels like Safety is experienced as part of how work is done, not as an overlay. Teams feel clear about what good looks like and what will be supported. Typical activities and routines Leaders proactively use risk information to shape priorities and trade-offs. Leaders coach expectations into practice through observation, feedback, and follow-through. The same intent is visible from executive meetings through to pre-starts and contractor interfaces.
B4: 1.2 Leadership Accountability for Outcomes Leadership is explicitly accountable for safety outcomes and the performance of the safety system, not just compliance or incident rates. Focus Areas Formal accountability for safety in leadership performance measures Ownership of system performance and critical control health Leadership response to incidents, risk and system failures Consistency and fairness in how accountability is applied | C4: What it looks like Accountability exists mainly through lag indicators and compliance checks. Safety performance is measured, but ownership is unclear when system weaknesses are found. Actions are assigned, but follow-through depends on individual leaders. When incidents occur, focus leans toward individual performance rather than system performance. What it sounds like “We need to get our TRIFR down” as the primary measure of success. “We have trained them, so it’s on them now” “We just need people to follow the rules” What it feels like Accountability is inconsistent and can feel reactive or event-driven. People see safety as something leaders talk about, but not always something leaders own. Typical activities and routines Incident reviews occur, but governance changes are rare. Corrective actions are created, but learning is not consistently embedded across teams. | D4: What it looks like Leadership accountability expands beyond injury rates to include system performance elements. Leaders have defined accountabilities for risk, controls, assurance activities, and actions. Performance discussions include leading indicators and the health of controls for serious risks. Incident response increasingly looks at system causes and leadership decisions. What it sounds like “What failed in the system that allowed this” “Which control should have prevented this, and was it verified” “What are we changing at leadership level” What it feels like Accountability feels more structured and fair, though not yet consistent everywhere. Leaders are increasingly expected to own improvement, not delegate it. Typical activities and routines Leaders regularly review action closure, recurring issues, and critical control performance. Leaders are more likely to resource fixes and remove barriers raised by the workforce. | E4: What it looks like Leadership accountability is clearly linked to system performance, risk control, and learning outcomes. Leaders are accountable for the integrity of critical controls and the effectiveness of governance routines. Accountability is consistent across seniority levels and business units. Following serious events, leadership decisions, governance structures, and resourcing are adjusted. What it sounds like “We own this risk and we own the controls” “We will not accept unknown control health” “We will change the way we govern this work, not just update a procedure” What it feels like Accountability is predictable, risk-based, and focused on improvement rather than blame. People trust that raising issues will lead to meaningful action, not punishment or silence. Typical activities and routines Leaders use assurance results, data trends, and learning to make visible changes in priorities and operations. Leaders actively verify control health and systematically address recurring weaknesses. Contractors are held to the same accountability expectations through clear oversight and governance.
A5: DECISION RIGHTS & GOVERNANCE STRUCTURE | B5: Intent: Clear, consistent, and transparent decision-making structures enable timely, risk-informed decisions for high-risk work, ensuring that authority, escalation, and oversight are unambiguous and operate effectively under both routine and pressured conditions.
B6: 2.1 Decision Rights for High-Risk Work Decision rights for high-risk work are clear, consistently applied, and understood across all levels, ensuring timely, risk-informed decisions and effective stop-work authority. Focus Areas Clarity of approval, escalation, and stop-work authority Consistent application of decision rules in practice Alignment between documented decision rights and real decisions Functionality of escalation pathways under pressure | C6: What it looks like Decision rules for high-risk work exist in some documents, but they are scattered, incomplete, or not well understood. Different leaders give different answers about who can approve, escalate, or stop work. Stop-work authority exists in policy but is rarely exercised in practice. Approvals are often driven by urgency, relationships, or hierarchy rather than clear criteria. What it sounds like “Check with your supervisor.” “Just get sign-off and keep moving.” “We can sort the paperwork later.” “It depends who you ask.” What it feels like People are uncertain about their authority under pressure. Workers hesitate to stop work unless explicitly told to. Decisions can feel personalised rather than system-based. Typical activities and routines High-risk permits or approvals exist but are treated as administrative steps. Escalation happens inconsistently and often only after something goes wrong. Decision making is reactive rather than planned. | D6: What it looks like A formal Decision Rights Matrix or equivalent exists and is reasonably well understood. Roles for approval, escalation, and stop-work are clearer, particularly for high-risk tasks. Most leaders follow the agreed decision pathways, especially for major risks. There is growing recognition that escalation is legitimate rather than a failure. What it sounds like “Who is the approver for this level of risk?” “Let’s escalate before we proceed.” “We need to verify the controls before we move forward.” “That decision sits with [role], not with us.” What it feels like People are more confident about who decides what. Stopping work is becoming more acceptable, though still uneven. Decision making feels more structured, even if not yet flawless. Typical activities and routines High-risk approvals generally follow a defined pathway. Leaders increasingly reference decision rules in meetings and planning. Escalation occurs more often, though sometimes still late or under pressure. | E6: What it looks like Decision rights are clearly defined, widely understood, and consistently applied across sites and contractors. Stop-work authority is genuinely embedded and used as a normal part of operations when controls degrade. Escalation pathways function effectively even under schedule or commercial pressure. Decision rights are stress-tested and refined based on real experience. What it sounds like “This exceeds our threshold, so we escalate.” “We will pause until the right approver reviews this.” “If we can’t verify the control, we don’t proceed.” “Let’s review whether our decision rules still make sense.” What it feels like People trust the system and know exactly what to do when risk changes. Stopping work is seen as responsible, not disruptive. Decisions feel predictable, fair, and risk-based rather than political. Typical activities and routines Leaders actively coach decision rights in real situations. Escalation happens early, not at crisis point. Decision rules are periodically reviewed and improved based on lessons learned.
B7: 2.2 Governance Forums and Structure A clear and effective governance structure enables purposeful safety decision-making, oversight, and accountability across the organisation. Focus Areas Clarity of governance structure, roles, and forums Quality and purposefulness of safety meetings and reviews Decision-making, action tracking, and follow-through Flow of safety information between frontline and leadership | C7: What it looks like Safety meetings and forums exist but are inconsistent in purpose or quality. Agendas tend to focus on incidents, compliance, or reporting rather than real risk. Actions are recorded, but closure is uneven and follow-up is weak. Frontline information rarely meaningfully shapes leadership discussions. What it sounds like “We need to get through the agenda.” “Let’s just note that for next time.” “We’ll take that offline.” “Same issues again this month.” What it feels like Meetings feel routine rather than valuable. Workers are unsure whether raising issues will lead to change. Governance feels like a reporting exercise rather than decision-making. Typical activities and routines Regular meetings occur but vary widely between sites or teams. Safety is discussed, but rarely changes priorities or resourcing. Information tends to flow upward slowly or not at all. | D7: What it looks like Governance structure is clearer, with defined forums, roles, and cadence. Safety meetings increasingly focus on high-risk activities, controls, and trends. Actions are more consistently tracked and closed. There is growing visibility of frontline issues at leadership level. What it sounds like “What are our top risks this month?” “Which actions are still open, and why?” “What is this telling us about our system?” “We need to hear from the site on this.” What it feels like Meetings feel more purposeful and less like a formality. Leaders appear more engaged with real safety issues. Workers begin to see that their concerns can influence decisions. Typical activities and routines Standing agendas include risk, controls, and learning rather than only incidents. Leadership forums review trends and recurring issues, not just one-off events. Action tracking becomes more visible and disciplined. | E7: What it looks like Governance structure is clearly defined, understood, and consistently applied across the organisation. Safety forums actively shape strategy, priorities, and resourcing. Decisions are transparent, well documented, and clearly linked to risk information. Information flows smoothly between frontline, supervisors, and executives in both directions. What it sounds like “Based on this trend, we need to change our approach.” “We will allocate resources to address this systemic issue.” “What are we hearing from the field that we need to act on?” “Let’s close the loop and communicate the outcome.” What it feels like Governance feels alive rather than bureaucratic. People trust that raising issues will lead to meaningful action. Safety decision-making feels integrated with how the business runs. Typical activities and routines Leaders routinely use governance forums to make real risk-based decisions. Frontline insights directly influence leadership priorities. Governance processes are reviewed and refined based on effectiveness, not just compliance.
A8: LEGAL & RISK GOVERNANCE | B8: Intent: Legal duties and risk boundaries are systematically translated into practical controls and decision rules, ensuring that governance is defensible, consistent, and aligned to the organisation’s tolerance for risk.
B9: 3.1 Translation of Legal Duties Legal duties are systematically translated into practical controls and accountabilities so governance is defensible and operationally meaningful. Focus Areas Currency and relevance of the legal register Clear mapping of legal duties to controls and roles Use of legal requirements in risk assessments and procedures Systematic updates when laws or standards change | C9: What it looks like A legal register exists, but it is treated as a compliance artefact rather than an operational tool. Legal duties are listed, but not clearly connected to real controls, procedures, or accountable roles. Risk assessments and procedures reference legislation inconsistently, if at all. Updates to legal requirements tend to be reactive, often triggered by audits or incidents. What it sounds like “We have a legal register somewhere.” “That’s covered in the procedure.” “HSE will look after the legal stuff.” “We’ll update it when we get audited.” What it feels like Legal compliance feels separate from how work is actually done. Teams experience legal requirements as paperwork rather than as risk controls. Leaders see legal compliance as HSE’s responsibility, not a shared governance duty. Typical activities and routines The legal register is reviewed irregularly or only when required. Procedures exist, but their connection to legal duties is not obvious to users. Risk assessments are often generic and not clearly grounded in legal obligations. | D9: What it looks like The legal register is current and more clearly structured, with visible links to key controls. Legal duties are increasingly mapped to specific procedures and accountable roles. Risk assessments more regularly reference relevant legal requirements, especially for high-risk work. Changes in law or standards trigger updates to some procedures or controls, though not always systematically. What it sounds like “Which legal duty relates to this control?” “We need to update that procedure because the standard changed.” “Who owns compliance for this requirement?” “Let’s check if our controls still meet the regulation.” What it feels like Legal requirements begin to feel more relevant to operational decision-making. Leaders are more aware that legal duties shape risk controls, not just paperwork. Compliance feels more structured, though still uneven across the business. Typical activities and routines Legal register reviews are scheduled and involve relevant functions, not only HSE. Some procedures explicitly reference applicable legal duties. High-risk work planning more consistently considers legal requirements. | E9: What it looks like The legal register is a live governance tool that clearly maps duties to critical controls, procedures, and accountable roles. Legal compliance actively informs risk priorities, control design, and decision-making. Changes in legislation or standards automatically trigger systematic reviews of controls, procedures, and training. Legal translation is consistent across sites, projects, and contractors. What it sounds like “This control exists because of this specific legal duty.” “Before we change this process, we need to confirm legal implications.” “Our governance needs to evolve with the new standard.” “Show me how this meets our legal obligations in practice.” What it feels like Legal duties are experienced as part of how safe work is designed, not as external pressure. Teams understand why controls exist, not just how to follow them. Leaders treat legal compliance as a core governance responsibility, not a box-ticking exercise. Typical activities and routines Legal changes trigger structured reviews of risk assessments, controls, and training. Legal mapping is visible in procedures, permits, and critical control documentation. Assurance activities routinely test whether legal duties are being met in practice, not just on paper.
B10: 3.2 Risk Appetite and Decision Boundaries Clear and shared risk boundaries guide consistent, defensible decision-making for routine and high-risk work. Focus Areas Existence and clarity of a documented risk appetite Consistent application of risk boundaries in decisions Alignment between risk appetite, approvals, and planning Leadership intervention when risk boundaries are approached | C10: What it looks like Risk appetite is informal, implicit, or described in vague terms. Leaders often make decisions based on experience, urgency, or commercial pressure rather than clear boundaries. Similar risks may be treated differently depending on who is involved. Risk acceptance is rarely documented in a structured or transparent way. What it sounds like “We just have to get the job done.” “We’ve always done it this way.” “It depends on the situation.” “We’ll manage it as we go.” What it feels like Risk tolerance feels inconsistent and unpredictable. Workers are unsure where the organisation’s true boundaries lie. Decisions can feel personality-driven rather than principle-driven. Typical activities and routines Risk assessments are completed, but thresholds for acceptance are unclear. Approvals are often negotiated rather than based on defined criteria. There is little visible link between risk decisions and any formal risk appetite. | D10: What it looks like A documented risk appetite exists, though it may still be high-level. Leaders increasingly reference risk boundaries in planning and approvals. There is more consistency in how similar risks are treated, particularly for high-risk work. Risk acceptance is more often documented, but rationale may still vary. What it sounds like “Does this fall within our risk appetite?” “We need to justify why we’re accepting this risk.” “This is above our threshold, so we need escalation.” “Let’s check if this aligns with our risk boundaries.” What it feels like Decision-making feels more structured and less arbitrary. Teams have a clearer sense of what risks are unacceptable. Leaders are more proactive in questioning risky situations. Typical activities and routines Risk appetite is referenced in key governance forums and approvals. High-risk work planning more consistently considers defined thresholds. Leaders increasingly intervene when risks approach boundaries. | E10: What it looks like Risk appetite is clearly defined, operationalised, and embedded in decision-making across the organisation. Approvals, planning, and resource allocation consistently reflect agreed risk boundaries. Leaders proactively intervene when risks approach or exceed thresholds. The organisation can clearly and confidently justify high-risk decisions to regulators, clients, or stakeholders. What it sounds like “This exceeds our risk appetite, so we will not proceed.” “We need to redesign the work to bring this within our boundaries.” “Our risk appetite guides how we prioritise and resource this.” “Here is why this decision is defensible.” What it feels like Risk decisions feel principled, consistent, and transparent. Workers trust that the organisation will not knowingly accept unacceptable risk. Leaders are visibly committed to staying within defined boundaries, even under pressure. Typical activities and routines Risk appetite is integrated into procedures, permits, and decision rights. Leaders routinely discuss risk boundaries in planning and governance forums. When boundaries are challenged, work is paused, redesigned, or resourced differently rather than pushed through.
A11: ESCALATION, PSYCHOLOGICAL SAFETY & LEARNING INTO GOVERNANCE | B11: Intent: The organisation actively encourages and protects upward flow of risk information, fosters psychological safety, and ensures that learning from incidents, near misses, and operational experience meaningfully reshapes leadership decisions and system design.
B12: 4.1 Escalation Pathways and Speak-Up Clear, trusted, and accessible escalation pathways enable anyone to raise safety concerns without fear and with timely response. Focus Areas Clarity and accessibility of speak-up and escalation routes Defined response timeframes and feedback loops Protection from retaliation when concerns are raised Evidence that issues raised lead to visible action | C12: What it looks like A formal speak-up or escalation process exists on paper, but awareness and use are patchy. Different teams rely on different informal routes to raise concerns. Timeframes for response are unclear or inconsistently applied. Issues are sometimes logged but outcomes are not always visible to those who raised them. What it sounds like “Just tell your supervisor.” “We’ll look into it.” “That’s probably for HSE to handle.” “We don’t want to make a big deal out of it.” What it feels like People are unsure whether raising concerns will lead to anything meaningful. Speaking up can feel risky or dependent on who your leader is. There is a sense that escalation is tolerated rather than encouraged. Typical activities and routines Concerns are raised inconsistently and often only when risk is obvious. Follow-up communication to reporters is sporadic. Escalation tends to happen after problems escalate rather than early. | D12: What it looks like Clear escalation routes are defined and generally understood across most teams. Response timeframes exist and are more consistently applied. There is visible action following some escalations, particularly for high-risk issues. Leaders increasingly treat escalation as legitimate rather than problematic. What it sounds like “If you’re unsure, escalate it.” “Let’s raise this before it gets worse.” “We’ll close the loop with you once we’ve reviewed it.” “Thanks for bringing that forward.” What it feels like People are more confident that raising concerns will lead to action. Speaking up is becoming more normal, though still uneven across areas. There is growing trust in formal escalation pathways. Typical activities and routines Issues are escalated earlier, particularly for high-risk work. Leaders provide more frequent feedback on actions taken. Formal channels (hotlines, reporting systems, or forums) are used alongside face-to-face escalation. | E12: What it looks like Escalation pathways are clear, widely understood, and consistently used across employees and contractors. Defined response timeframes are met as a norm, not an exception. People who raise concerns consistently receive timely feedback and see visible outcomes. Retaliation is actively prevented and addressed if it occurs. What it sounds like “We want to hear about this early.” “Thank you for raising that — here’s what we’re doing.” “If you’re uncomfortable, use the formal channel.” “We will pause until this is resolved.” What it feels like Speaking up feels safe, expected, and valued. Escalation is seen as a sign of a strong system, not a failure. People trust that concerns will be taken seriously regardless of seniority. Typical activities and routines Leaders actively invite escalation and check for concerns in the field. Feedback loops are systematic and visible. Patterns in escalations are reviewed at governance forums to prevent recurrence.
B13: 4.2 Psychological Safety Leaders create conditions where people feel safe to surface risk, challenge decisions, and speak openly about problems. Focus Areas Leadership behaviours that invite challenge and bad news Quality of dialogue in meetings and decision forums Absence of blame and fear of consequences for speaking up Evidence that constructive dissent is valued and acted upon | C13: What it looks like Overt fear is uncommon, but people are cautious about challenging decisions. Meetings are polite but often avoid difficult or uncomfortable topics. Dissent tends to be indirect or raised privately rather than openly. Blame still surfaces after incidents, even if unintentionally. What it sounds like “Let’s not rock the boat.” “We’ll take that offline.” “We should be careful how we phrase this.” Silence when tough questions are asked. What it feels like People are comfortable raising minor issues but hesitant to surface serious concerns. There is an unspoken sense that speaking up could have consequences. Safety conversations feel somewhat controlled rather than open. Typical activities and routines Leaders ask for input, but mainly from the same confident voices. Meetings focus more on reporting than real discussion of risk. Challenging topics are often deferred rather than explored. | D13: What it looks like Leaders more actively invite challenge and bad news in meetings. Constructive dissent is increasingly visible and tolerated. People are more willing to speak up about risk, especially when prompted. Blame is reducing, though not yet eliminated. What it sounds like “What are we missing here?” “I’d like to hear a different perspective.” “Let’s talk openly about what could go wrong.” “We’re not here to point fingers.” What it feels like People are more confident that they can speak up without negative consequences. Discussions feel more genuine, though still inconsistent across leaders. There is growing trust that concerns will be heard. Typical activities and routines Leaders consciously create space for discussion in meetings. Workers increasingly raise risks earlier rather than waiting. Leaders model vulnerability by acknowledging uncertainty or mistakes. | E13: What it looks like Healthy debate and constructive challenge are routine across all levels. Leaders actively seek out dissenting views, especially on high-risk decisions. People feel safe raising uncomfortable truths, even about leadership decisions. Blame is consistently replaced with system thinking. What it sounds like “Who disagrees, and why?” “What risks are we not seeing?” “Thank you for challenging that.” “Let’s focus on how the system failed, not who.” What it feels like Psychological safety is deeply embedded, not leader-dependent. Speaking up feels normal, expected, and valued. People trust that honesty will lead to improvement, not punishment. Typical activities and routines Leaders publicly acknowledge and reward people who surface risk early. Difficult conversations occur openly and constructively. Teams routinely reflect on how they handle dissent and improve their dialogue.
B14: 4.3 Learning Feeding Back into Governance Insights from incidents, near misses, and operational experience actively reshape leadership decisions and system design. Focus Areas Quality and depth of incident investigations Evidence that learning leads to system or governance changes Sharing of lessons beyond the immediate site or team Continuous refinement of decision rules, controls, or structures | C14: What it looks like Serious incidents are investigated, but learning often remains local. Corrective actions tend to focus on immediate fixes rather than systemic issues. Governance structures or decision rules rarely change as a result of incidents. Lessons learned are inconsistently shared across sites or teams. What it sounds like “We need to close out these actions.” “Let’s update the procedure.” “This was a one-off.” “We’ll remind people to be careful.” What it feels like Learning feels reactive rather than proactive. Teams may repeat similar issues in different areas. Investigations can feel like compliance exercises rather than opportunities to improve. Typical activities and routines Investigations focus heavily on proximate causes. Actions are tracked but not always evaluated for effectiveness. Knowledge sharing is ad hoc and depends on individuals. | D14: What it looks like Investigations increasingly identify systemic contributors, not just immediate causes. Learning more regularly leads to updates in procedures, controls, or training. Lessons learned are shared beyond the immediate site or team. Some leadership-level changes occur following significant events. What it sounds like “What does this tell us about our system?” “We need to change how we manage this risk.” “Let’s share this with other sites.” “What can we do differently next time?” What it feels like There is growing recognition that incidents reveal system weaknesses. Learning is becoming more purposeful, though still uneven. People see some tangible improvements after events. Typical activities and routines Cross-site learning forums or bulletins are used more regularly. Leaders are more involved in reviewing investigation findings. Controls or decision rules are occasionally revised based on learning. | E14: What it looks like Investigations consistently examine leadership decisions, governance structures, and system design. Learning routinely drives changes to governance, decision rules, or critical controls. Lessons are systematically shared, embedded, and verified across the organisation. The system visibly evolves over time based on real operational experience. What it sounds like “What do we need to change in how we govern this work?” “This event shows our decision rules need refinement.” “Let’s update our risk boundaries based on this learning.” “How will we verify that this change actually reduces risk?” What it feels like Learning feels continuous, not event-driven. People trust that incidents lead to meaningful system improvement. The organisation feels more resilient over time, not just reactive. Typical activities and routines Leadership reviews regularly translate investigation insights into governance changes. Decision rights, controls, and risk appetite are refined based on evidence. Assurance activities test whether lessons have been effectively embedded.

Sheet Scoring Worksheet
B2: Governance Core Assessment
B3: Scoring Worksheet
B5: Organisation
B6: Facility/ Asset | H6: Team (if required)
B7: Assessor Name/s | H7: Assessment Date
B10: Category | C10: Intent and fundamental criteria | F10: Strength | H10: Scoring Indicators | L10: Self-Assessment or Baseline
C11: # | D11: Topic | E11: Clauses | F11: Indicators | G11: Don't Touch | H11: Consistent | I11: Quality | J11: Sustained | K11: Don't Touch | L11: Score | M11: Comments / Recommendations
B12: LEADERSHIP & ACCOUNTABILITY | C12: 1.1 | D12: Leadership Intent and Expectations | E12: Clarity and consistency of leadership safety intent | F12: Reactive | G12: =IF(F12="Reactive","R",IF(F12="Proactive","P",IF(F12="Resilient","RE",""))) -> R | H12: C | I12: Q | J12: S | K12: =G12&H12&I12&J12 -> RCQS | L12: =VLOOKUP(K12,Lists!B:C,2,FALSE) -> 3
E13: Translation of intent into roles, expectations and decisions | F13: Resilient | G13: =IF(F13="Reactive","R",IF(F13="Proactive","P",IF(F13="Resilient","RE",""))) -> RE | H13: C | I13: X | J13: X | K13: =G13&H13&I13&J13 -> RECXX | L13: =IFERROR(VLOOKUP(K13,Lists!B:C,2,FALSE),"") -> 7
E14: Shared understanding of safety intent across leadership layers | G14: =IF(F14="Reactive","R",IF(F14="Proactive","P",IF(F14="Resilient","RE",""))) | K14: =G14&H14&I14&J14 | L14: =IFERROR(VLOOKUP(K14,Lists!B:C,2,FALSE),"")
E15: Visible alignment between what leaders say and what they do | G15: =IF(F15="Reactive","R",IF(F15="Proactive","P",IF(F15="Resilient","RE",""))) | K15: =G15&H15&I15&J15 | L15: =IFERROR(VLOOKUP(K15,Lists!B:C,2,FALSE),"")
C16: 1.2 | D16: Leadership Accountability for Outcomes | E16: Formal accountability for safety in leadership performance measures | G16: =IF(F16="Reactive","R",IF(F16="Proactive","P",IF(F16="Resilient","RE",""))) | K16: =G16&H16&I16&J16 | L16: =IFERROR(VLOOKUP(K16,Lists!B:C,2,FALSE),"")
E17: Ownership of system performance and critical control health | G17: =IF(F17="Reactive","R",IF(F17="Proactive","P",IF(F17="Resilient","RE",""))) | K17: =G17&H17&I17&J17 | L17: =IFERROR(VLOOKUP(K17,Lists!B:C,2,FALSE),"")
E18: Leadership response to incidents, risk and system failures | G18: =IF(F18="Reactive","R",IF(F18="Proactive","P",IF(F18="Resilient","RE",""))) | K18: =G18&H18&I18&J18 | L18: =IFERROR(VLOOKUP(K18,Lists!B:C,2,FALSE),"")
E19: Consistency and fairness in how accountability is applied | G19: =IF(F19="Reactive","R",IF(F19="Proactive","P",IF(F19="Resilient","RE",""))) | K19: =G19&H19&I19&J19 | L19: =IFERROR(VLOOKUP(K19,Lists!B:C,2,FALSE),"")
B20: DECISION RIGHTS & GOVERNANCE STRUCTURE | C20: 2.1 | D20: Decision Rights for High-Risk Work | E20: Clarity of approval, escalation, and stop-work authority | G20: =IF(F20="Reactive","R",IF(F20="Proactive","P",IF(F20="Resilient","RE",""))) | K20: =G20&H20&I20&J20 | L20: =IFERROR(VLOOKUP(K20,Lists!B:C,2,FALSE),"")
E21: Consistent application of decision rules in practice | G21: =IF(F21="Reactive","R",IF(F21="Proactive","P",IF(F21="Resilient","RE",""))) | K21: =G21&H21&I21&J21 | L21: =IFERROR(VLOOKUP(K21,Lists!B:C,2,FALSE),"")
E22: Alignment between documented decision rights and real decisions | G22: =IF(F22="Reactive","R",IF(F22="Proactive","P",IF(F22="Resilient","RE",""))) | K22: =G22&H22&I22&J22 | L22: =IFERROR(VLOOKUP(K22,Lists!B:C,2,FALSE),"")
E23: Functionality of escalation pathways under pressure | G23: =IF(F23="Reactive","R",IF(F23="Proactive","P",IF(F23="Resilient","RE",""))) | K23: =G23&H23&I23&J23 | L23: =IFERROR(VLOOKUP(K23,Lists!B:C,2,FALSE),"")
C24: 2.2 | D24: Decision Rights for High-Risk Work | E24: Clarity of governance structure, roles, and forums | G24: =IF(F24="Reactive","R",IF(F24="Proactive","P",IF(F24="Resilient","RE",""))) | K24: =G24&H24&I24&J24 | L24: =IFERROR(VLOOKUP(K24,Lists!B:C,2,FALSE),"")
E25: Quality and purposefulness of safety meetings and reviews | G25: =IF(F25="Reactive","R",IF(F25="Proactive","P",IF(F25="Resilient","RE",""))) | K25: =G25&H25&I25&J25 | L25: =IFERROR(VLOOKUP(K25,Lists!B:C,2,FALSE),"")
E26: Decision-making, action tracking, and follow-through | G26: =IF(F26="Reactive","R",IF(F26="Proactive","P",IF(F26="Resilient","RE",""))) | K26: =G26&H26&I26&J26 | L26: =IFERROR(VLOOKUP(K26,Lists!B:C,2,FALSE),"")
E27: Flow of safety information between frontline and leadership | G27: =IF(F27="Reactive","R",IF(F27="Proactive","P",IF(F27="Resilient","RE",""))) | K27: =G27&H27&I27&J27 | L27: =IFERROR(VLOOKUP(K27,Lists!B:C,2,FALSE),"")
B28: LEGAL & RISK GOVERNANCE | C28: 3.1 | D28: Translation of Legal Duties | E28: Currency and relevance of the legal register | G28: =IF(F28="Reactive","R",IF(F28="Proactive","P",IF(F28="Resilient","RE",""))) | K28: =G28&H28&I28&J28 | L28: =IFERROR(VLOOKUP(K28,Lists!B:C,2,FALSE),"")
E29: Clear mapping of legal duties to controls and roles | G29: =IF(F29="Reactive","R",IF(F29="Proactive","P",IF(F29="Resilient","RE",""))) | K29: =G29&H29&I29&J29 | L29: =IFERROR(VLOOKUP(K29,Lists!B:C,2,FALSE),"")
E30: Use of legal requirements in risk assessments and procedures | G30: =IF(F30="Reactive","R",IF(F30="Proactive","P",IF(F30="Resilient","RE",""))) | K30: =G30&H30&I30&J30 | L30: =IFERROR(VLOOKUP(K30,Lists!B:C,2,FALSE),"")
E31: Systematic updates when laws or standards change | G31: =IF(F31="Reactive","R",IF(F31="Proactive","P",IF(F31="Resilient","RE",""))) | K31: =G31&H31&I31&J31 | L31: =IFERROR(VLOOKUP(K31,Lists!B:C,2,FALSE),"")
C32: 3.2 | D32: Risk Appetite and Decision Boundaries | E32: Existence and clarity of a documented risk appetite | G32: =IF(F32="Reactive","R",IF(F32="Proactive","P",IF(F32="Resilient","RE",""))) | K32: =G32&H32&I32&J32 | L32: =IFERROR(VLOOKUP(K32,Lists!B:C,2,FALSE),"")
E33: Consistent application of risk boundaries in decisions | G33: =IF(F33="Reactive","R",IF(F33="Proactive","P",IF(F33="Resilient","RE",""))) | K33: =G33&H33&I33&J33 | L33: =IFERROR(VLOOKUP(K33,Lists!B:C,2,FALSE),"")
E34: Alignment between risk appetite, approvals, and planning | G34: =IF(F34="Reactive","R",IF(F34="Proactive","P",IF(F34="Resilient","RE",""))) | K34: =G34&H34&I34&J34 | L34: =IFERROR(VLOOKUP(K34,Lists!B:C,2,FALSE),"")
E35: Leadership intervention when risk boundaries are approached | G35: =IF(F35="Reactive","R",IF(F35="Proactive","P",IF(F35="Resilient","RE",""))) | K35: =G35&H35&I35&J35 | L35: =IFERROR(VLOOKUP(K35,Lists!B:C,2,FALSE),"")
B36: ESCALATION, PSYCHOLOGICAL SAFETY & LEARNING INTO GOVERNANCE | C36: 4.1 | D36: Escalation Pathways and Speak-Up | E36: Clarity and accessibility of speak-up and escalation routes | G36: =IF(F36="Reactive","R",IF(F36="Proactive","P",IF(F36="Resilient","RE",""))) | K36: =G36&H36&I36&J36 | L36: =IFERROR(VLOOKUP(K36,Lists!B:C,2,FALSE),"")
E37: Defined response timeframes and feedback loops | G37: =IF(F37="Reactive","R",IF(F37="Proactive","P",IF(F37="Resilient","RE",""))) | K37: =G37&H37&I37&J37 | L37: =IFERROR(VLOOKUP(K37,Lists!B:C,2,FALSE),"")
E38: Protection from retaliation when concerns are raised | G38: =IF(F38="Reactive","R",IF(F38="Proactive","P",IF(F38="Resilient","RE",""))) | K38: =G38&H38&I38&J38 | L38: =IFERROR(VLOOKUP(K38,Lists!B:C,2,FALSE),"")
E39: Evidence that issues raised lead to visible action | G39: =IF(F39="Reactive","R",IF(F39="Proactive","P",IF(F39="Resilient","RE",""))) | K39: =G39&H39&I39&J39 | L39: =IFERROR(VLOOKUP(K39,Lists!B:C,2,FALSE),"")
C40: 4.2 | D40: Psychological Safety | E40: Leadership behaviours that invite challenge and bad news | G40: =IF(F40="Reactive","R",IF(F40="Proactive","P",IF(F40="Resilient","RE",""))) | K40: =G40&H40&I40&J40 | L40: =IFERROR(VLOOKUP(K40,Lists!B:C,2,FALSE),"")
E41: Quality of dialogue in meetings and decision forums | G41: =IF(F41="Reactive","R",IF(F41="Proactive","P",IF(F41="Resilient","RE",""))) | K41: =G41&H41&I41&J41 | L41: =IFERROR(VLOOKUP(K41,Lists!B:C,2,FALSE),"")
E42: Absence of blame and fear of consequences for speaking up | G42: =IF(F42="Reactive","R",IF(F42="Proactive","P",IF(F42="Resilient","RE",""))) | K42: =G42&H42&I42&J42 | L42: =IFERROR(VLOOKUP(K42,Lists!B:C,2,FALSE),"")
E43: Evidence that constructive dissent is valued and acted upon | G43: =IF(F43="Reactive","R",IF(F43="Proactive","P",IF(F43="Resilient","RE",""))) | K43: =G43&H43&I43&J43 | L43: =IFERROR(VLOOKUP(K43,Lists!B:C,2,FALSE),"")
C44: 4.3 | D44: Learning Feeding Back into Governance | E44: Quality and depth of incident investigations | G44: =IF(F44="Reactive","R",IF(F44="Proactive","P",IF(F44="Resilient","RE",""))) | K44: =G44&H44&I44&J44 | L44: =IFERROR(VLOOKUP(K44,Lists!B:C,2,FALSE),"")
...

Sheet Intent Statement
A1: Category | B1: Intent and fundamental criteria | C1: Reactive | D1: Proactive | E1: Resilient
A2: LEADERSHIP & ACCOUNTABILITY | B2: Intent: Leadership sets the direction for safety, visibly owns risk, and is accountable for system performance and outcomes, ensuring that safety is consistently prioritised in decisions, behaviours, and resource allocation across the organisation. 1.1 Leadership Intent and Expectations Clarity and consistency of leadership safety intent Translation of intent into roles, expectations and decisions Shared understanding of safety intent across leadership layers Visible alignment between what leaders say and what they do 1.2 Leadership Accountability for Outcomes Formal accountability for safety in leadership performance measures Ownership of system performance and critical control health Leadership response to incidents, risk and system failures Consistency and fairness in how accountability is applied | C2: There is a visible commitment to safety, but intent is often expressed as broad values rather than clear decision rules. | D2: Leaders are broadly aligned in their safety messaging, and intent is increasingly translated into expectations for how work is planned and decided. | E2: Leadership intent is operational, consistent, and actively shapes strategy, resourcing, and risk trade-offs.
C3: Safety expectations exist, but application varies across leaders, teams, and sites. | D3: Most leaders understand and reference safety intent, particularly for high-risk work. | E3: Safety expectations are consistently applied across all layers of the organisation, including contractors.
C4: Accountability is primarily tied to compliance and lagging metrics. | D4: Leaders are increasingly accountable for system performance and critical control health. | E4: Leaders visibly own the health of the safety system and are accountable for learning, control effectiveness, and governance outcomes.
C5: When things go wrong, responses tend to focus on individuals rather than the system. | D5: Incident responses more often examine system contributors and leadership decisions. | E5: After significant events, leadership decisions, governance structures, and resourcing are routinely adjusted.
C6: Safety is still largely leader dependent. | D6: Ownership of safety is growing beyond formal leadership roles. | E6: Safety is owned across the organisation, with leaders modelling the expected behaviours under pressure.
A7: DECISION RIGHTS & GOVERNANCE STRUCTURE | B7: Intent: Clear, consistent, and transparent decision-making structures enable timely, risk-informed decisions for high-risk work, ensuring that authority, escalation, and oversight are unambiguous and operate effectively under both routine and pressured conditions. 2.1 Decision Rights for High-Risk Work Clarity of approval, escalation, and stop-work authority Consistent application of decision rules in practice Alignment between documented decision rights and real decisions Functionality of escalation pathways under pressure 2.2 Governance Forums and Structure Clarity of governance structure, roles, and forums Quality and purposefulness of safety meetings and reviews Decision-making, action tracking, and follow-through Flow of safety information between frontline and leadership | C7: Decision rules for high-risk work exist, but are not consistently understood or applied. | D7: A formal decision rights structure exists and is generally understood across leadership layers. | E7: Decision rights are clear, widely understood, and consistently applied across sites and contractors.
C8: Stop-work authority exists in policy, but is rarely exercised in practice. | D8: Stop-work is becoming more acceptable, particularly for clearly high-risk situations. | E8: Stopping work is normalised when controls are uncertain or degraded.
C9: Governance forums operate, but often feel like reporting exercises rather than decision-making spaces. | D9: Safety forums are more purposeful and increasingly focused on risk, controls, and trends. | E9: Governance forums actively shape strategy, priorities, and resourcing.
C10: Actions are recorded but follow-through is inconsistent. | D10: Action tracking and closure are becoming more disciplined and visible. | E10: Decisions are transparent, well documented, and clearly linked to risk information.
C11: Information from the frontline rarely meaningfully influences leadership decisions. | D11: There is growing visibility of frontline issues at leadership level. | E11: Two-way flow of safety information is strong, timely, and trusted.
A12: LEGAL & RISK GOVERNANCE | B12: Intent: Legal duties and risk boundaries are systematically translated into practical controls and decision rules, ensuring that governance is defensible, consistent, and aligned to the organisation’s tolerance for risk. 3.1 Translation of Legal Duties Currency and relevance of the legal register Clear mapping of legal duties to controls and roles Use of legal requirements in risk assessments and procedures Systematic updates when laws or standards change 3.2 Risk Appetite and Decision Boundaries Existence and clarity of a documented risk appetite Consistent application of risk boundaries in decisions Alignment between risk appetite, approvals, and planning Leadership intervention when risk boundaries are approached | C12: A legal register exists, but is treated mainly as a compliance artefact rather than an operational tool. | D12: The legal register is current and more clearly linked to key controls and accountable roles. | E12: The legal register is a live governance tool that actively shapes control design and decision-making.
C13: Legal duties are not consistently reflected in risk assessments or procedures. | D13: High-risk planning more regularly considers relevant legal requirements. | E13: Legal duties are embedded into risk assessments, permits, and critical controls as standard practice.
C14: Risk appetite is largely implicit and decisions are often driven by urgency or experience. | D14: A documented risk appetite exists and is increasingly referenced in approvals and planning. | E14: Risk appetite is fully operationalised and consistently guides decisions across the business.
C15: Similar risks are often treated differently depending on who is involved. | D15: There is growing consistency in how comparable risks are managed. | E15: Risk decisions are principled, transparent, and defensible to regulators, clients, and stakeholders.
C16: Updates to laws or standards are reactive. | D16: Legal changes trigger some procedural or control updates. | E16: Legal changes automatically trigger systematic reviews of controls, procedures, and training.
A17: ESCALATION, PSYCHOLOGICAL SAFETY & LEARNING INTO GOVERNANCE | B17: Intent: The organisation actively encourages and protects upward flow of risk information, fosters psychological safety, and ensures that learning from incidents, near misses, and operational experience meaningfully reshapes leadership decisions and system design. 4.1 Escalation Pathways and Speak-Up Clarity and accessibility of speak-up and escalation routes Defined response timeframes and feedback loops Protection from retaliation when concerns are raised Evidence that issues raised lead to visible action 4.2 Psychological Safety Leadership behaviours that invite challenge and bad news Quality of dialogue in meetings and decision forums Absence of blame and fear of consequences for speaking up Evidence that constructive dissent is valued and acted upon 4.3 Learning Feeding Back into Governance Quality and depth of incident investigations Evidence that learning leads to system or governance changes Sharing of lessons beyond the immediate site or team Continuous refinement of decision rules, controls, or structures | C17: Formal speak-up channels exist, but awareness and trust are uneven. | D17: Clear escalation routes are understood across most teams, with improving response times. | E17: Escalation pathways are clear, trusted, and used consistently by employees and contractors.
C18: People may raise issues, but feedback and visible outcomes are inconsistent. | D18: Leaders more regularly close the loop with those who speak up. | E18: Feedback loops are systematic, visible, and used to improve the system.
C19: Psychological safety is emerging, but challenge still feels uncomfortable. | D19: Leaders increasingly invite dissent and constructive challenge. | E19: Healthy debate is routine, and leaders actively seek out dissenting views.
C20: Investigations occur after serious events, but learning often stays local. | D20: Investigations more often identify systemic contributors, not just immediate causes. | E20: Investigations routinely examine leadership decisions, governance, and system design.
C21: Corrective actions focus on immediate fixes rather than systemic change. | D21: Learning more regularly leads to updates in controls or procedures. | E21: Learning consistently drives changes to governance, decision rights, and risk boundaries.
C22: The system feels reactive rather than proactive. | D22: Improvement is becoming more structured, though still uneven. | E22: The system is self-reinforcing and continuously evolving based on real operational experience.

Sheet Assessment Prompts
B1: Intent and Criteria to Assess | C1: Process Question Examples Use when conducting field assessments or desktop assessments with workers and leaders. | D1: People Question Examples Use when conducting field assessments or desktop assessments with workers and leaders. | E1: System-Based Queries/ Observations Use to validate use, quality and consistent use of systems to achieve governance objectives. | F1: Symbols/ Behaviours Observations Use to identify symbols or behaviours within the workplace during the assessment that indicate performance.
